Workbook

Sheet Task Tracker
A1: TEAM TASK & PRODUCTIVITY TRACKER
A2: Track assignments, deadlines, and workload across all team members and brands
A4: Task ID | B4: Task Name | C4: Assigned To | D4: Brand | E4: Task Type | F4: Priority | G4: Status | H4: Start Date | I4: Deadline | J4: Completion Date | K4: Notes
A5: TSK-001 | B5: Instagram Reels - Product Launch | C5: Dimas Prasetyo | D5: Tunova | E5: Social Media Post | F5: Medium | G5: In Progress | H5: 46117 | I5: 46123
A6: TSK-002 | B6: Facebook Ad Campaign Q2 | C6: Dimas Prasetyo | D6: Tunova | E6: Video Production | F6: Medium | G6: Not Started | H6: 46115 | I6: 46124
A7: TSK-003 | B7: Brand Guidelines Update | C7: Dewi Lestari | D7: Tunova | E7: Brand Guidelines | F7: High | G7: In Progress | H7: 46133 | I7: 46153
A8: TSK-004 | B8: Monthly Newsletter Draft | C8: Fajar Nugroho | D8: Tunova | E8: Email Marketing | F8: Medium | G8: Completed | H8: 46113 | I8: 46121 | J8: 46118
A9: TSK-005 | B9: TikTok Content Calendar | C9: Putri Wulandari | D9: Tunova | E9: Graphic Design | F9: High | G9: Completed | H9: 46116 | I9: 46121 | J9: 46118
A10: TSK-006 | B10: Product Photography Session | C10: Siti Rahayu | D10: Tunova | E10: Ad Management | F10: Medium | G10: Completed | H10: 46136 | I10: 46153 | J10: 46153
A11: TSK-007 | B11: Website Banner Design | C11: Fajar Nugroho | D11: Tunova | E11: Photography | F11: High | G11: In Review | H11: 46124 | I11: 46145
A12: TSK-008 | B12: Email Drip Campaign Setup | C12: Dewi Lestari | D12: Tunova | E12: Social Media Post | F12: Medium | G12: Completed | H12: 46115 | I12: 46125 | J12: 46125
A13: TSK-009 | B13: Influencer Outreach List | C13: Fajar Nugroho | D13: Tunova | E13: Email Marketing | F13: Medium | G13: In Progress | H13: 46124 | I13: 46138
A14: TSK-010 | B14: YouTube Video Editing | C14: Dewi Lestari | D14: Tunova | E14: Event Planning | F14: Low | G14: In Review | H14: 46132 | I14: 46140
A15: TSK-011 | B15: Blog Post - Industry Trends | C15: Hendra Wijaya | D15: Tunova | E15: Graphic Design | F15: Medium | G15: In Progress | H15: 46133 | I15: 46153
A16: TSK-012 | B16: Press Release Draft | C16: Dewi Lestari | D16: Tunova | E16: Social Media Post | F16: High | G16: Not Started | H16: 46123 | I16: 46138
A17: TSK-013 | B17: Social Media Audit Report | C17: Rizki Hidayat | D17: Tunova | E17: Copywriting | F17: Low | G17: In Review | H17: 46135 | I17: 46148
A18: TSK-014 | B18: Google Ads Optimization | C18: Dewi Lestari | D18: Tunova | E18: Content Strategy | F18: Low | G18: In Review | H18: 46117 | I18: 46128
A19: TSK-015 | B19: Landing Page Wireframe | C19: Budi Santoso | D19: Tunova | E19: Event Planning | F19: Medium | G19: In Progress | H19: 46131 | I19: 46147
A20: TSK-016 | B20: Customer Testimonial Video | C20: Maya Kusuma | D20: Natasha | E20: Ad Management | F20: High | G20: On Hold | H20: 46129 | I20: 46147
A21: TSK-017 | B21: Podcast Episode Editing | C21: Siti Rahayu | D21: Natasha | E21: Video Production | F21: High | G21: Not Started | H21: 46134 | I21: 46150
A22: TSK-018 | B22: Competitor Analysis Report | C22: Maya Kusuma | D22: Natasha | E22: Content Strategy | F22: Medium | G22: On Hold | H22: 46129 | I22: 46140
A23: TSK-019 | B23: Whitepapers Design Layout | C23: Hendra Wijaya | D23: Natasha | E23: Market Research | F23: Medium | G23: Completed | H23: 46130 | I23: 46141 | J23: 46139
A24: TSK-020 | B24: Trade Show Materials | C24: Siti Rahayu | D24: Natasha | E24: Content Strategy | F24: High | G24: Not Started | H24: 46136 | I24: 46147
A25: TSK-021 | B25: Holiday Campaign Planning | C25: Hendra Wijaya | D25: Natasha | E25: Photography | F25: Low | G25: Completed | H25: 46122 | I25: 46141 | J25: 46140
A26: TSK-022 | B26: SEO Content Brief | C26: Budi Santoso | D26: Natasha | E26: Graphic Design | F26: Medium | G26: Completed | H26: 46129 | I26: 46132 | J26: 46130
A27: TSK-023 | B27: Brand Awareness Survey | C27: Anita Sari | D27: Natasha | E27: Video Production | F27: Low | G27: Completed | H27: 46138 | I27: 46150 | J27: 46149
A28: TSK-024 | B28: Partnership Proposal Deck | C28: Adi Pratama | D28: Natasha | E28: Brand Guidelines | F28: Low | G28: Not Started | H28: 46128 | I28: 46133
A29: TSK-025 | B29: Weekly Analytics Report | C29: Hendra Wijaya | D29: Natasha | E29: Graphic Design | F29: Medium | G29: On Hold | H29: 46118 | I29: 46129
A30: TSK-026 | B30: Creative Brief - New Product | C30: Hendra Wijaya | D30: Natasha | E30: Content Strategy | F30: Low | G30: On Hold | H30: 46137 | I30: 46146
A31: TSK-027 | B31: Radio Ad Script | C31: Rina Fitriani | D31: Natasha | E31: Content Strategy | F31: Low | G31: In Review | H31: 46127 | I31: 46146
A32: TSK-028 | B32: Billboard Design Concept | C32: Anita Sari | D32: Natasha | E32: Copywriting | F32: High | G32: In Progress | H32: 46131 | I32: 46151
A33: TSK-029 | B33: App Store Screenshots | C33: Dewi Lestari | D33: Natasha | E33: Copywriting | F33: High | G33: Completed | H33: 46114 | I33: 46124 | J33: 46124
A34: TSK-030 | B34: Loyalty Program Email | C34: Adi Pratama | D34: NaavaGreen | E34: Video Production | F34: Medium | G34: In Progress | H34: 46128 | I34: 46137
A35: TSK-031 | B35: Webinar Presentation Slides | C35: Hendra Wijaya | D35: NaavaGreen | E35: Event Planning | F35: Low | G35: In Review | H35: 46128 | I35: 46138
A36: TSK-032 | B36: Annual Report Design | C36: Anita Sari | D36: NaavaGreen | E36: Copywriting | F36: High | G36: In Review | H36: 46124 | I36: 46140
A37: TSK-033 | B37: Social Listening Report | C37: Fajar Nugroho | D37: NaavaGreen | E37: Event Planning | F37: High | G37: In Review | H37: 46133 | I37: 46139
A38: TSK-034 | B38: Rebranding Mood Board | C38: Adi Pratama | D38: NaavaGreen | E38: Event Planning | F38: Medium | G38: Completed | H38: 46120 | I38: 46129 | J38: 46128
A39: TSK-035 | B39: Video Testimonials Edit | C39: Hendra Wijaya | D39: NaavaGreen | E39: Graphic Design | F39: Medium | G39: In Progress | H39: 46120 | I39: 46125
A40: TSK-036 | B40: Content Repurposing Plan | C40: Anita Sari | D40: NaavaGreen | E40: Video Production | F40: High | G40: On Hold | H40: 46113 | I40: 46118
A41: TSK-037 | B41: Content Repurposing Plan | C41: Anita Sari | D41: NaavaGreen | E41: Video Production | F41: High | G41: On Hold | H41: 46113 | I41: 46118
...

Sheet Team Members
A1: TEAM DIRECTORY
A3: Name | B3: Role | C3: Department | D3: Max Capacity (tasks/week)
A4: Adi Pratama | B4: Content Creator | C4: Content | D4: 5
A5: Siti Rahayu | B5: Graphic Designer | C5: Design | D5: 5
A6: Budi Santoso | B6: Social Media Manager | C6: Social Media | D6: 7
A7: Dewi Lestari | B7: Copywriter | C7: Content | D7: 7
A8: Rizki Hidayat | B8: Video Editor | C8: Production | D8: 7
A9: Putri Wulandari | B9: Campaign Manager | C9: Marketing | D9: 5
A10: Fajar Nugroho | B10: Content Strategist | C10: Strategy | D10: 7
A11: Anita Sari | B11: Email Specialist | C11: Marketing | D11: 4
A12: Hendra Wijaya | B12: Photographer | C12: Production | D12: 5
A13: Maya Kusuma | B13: Brand Manager | C13: Brand | D13: 7
A14: Dimas Prasetyo | B14: Market Analyst | C14: Research | D14: 4
A15: Rina Fitriani | B15: Event Coordinator | C15: Events | D15: 7

Sheet Brands
A1: BRAND DIRECTORY
A3: Brand Name | B3: Industry | C3: Status
A4: Tunova | B4: Technology | C4: Active
A5: Bank Mantap | B5: Finance | C5: Active
A6: Barklay | B6: Pet | C6: Active
A7: Natasha | B7: Beauty & Skincare | C7: Active
A8: NaavaGreen | B8: Beauty & Skincare | C8: Active

Sheet Summary
A1: TASK SUMMARY
A3: Total Tasks | B3: =COUNTA('Task Tracker'!A5:A200) -> 41
A4: Completed | B4: =COUNTIF('Task Tracker'!G5:G200,"Completed") -> 10
A5: In Progress | B5: =COUNTIF('Task Tracker'!G5:G200,"In Progress") -> 8
A6: Overdue (past deadline, not completed) | B6: =COUNTIFS('Task Tracker'!I5:I200,"<"&TODAY(),'Task Tracker'!G5:G200,"<>Completed") -> 20
A8: TASKS PER TEAM MEMBER
A9: Team Member | B9: Total | C9: Not Started | D9: In Progress | E9: In Review | F9: Completed
A10: Adi Pratama | B10: =COUNTIF('Task Tracker'!C$5:C$200,A10) -> 3 | C10: =COUNTIFS('Task Tracker'!C$5:C$200,A10,'Task Tracker'!G$5:G$200,"Not Started") -> 1 | D10: =COUNTIFS('Task Tracker'!C$5:C$200,A10,'Task Tracker'!G$5:G$200,"In Progress") -> 1 | E10: =COUNTIFS('Task Tracker'!C$5:C$200,A10,'Task Tracker'!G$5:G$200,"In Review") -> 0 | F10: =COUNTIFS('Task Tracker'!C$5:C$200,A10,'Task Tracker'!G$5:G$200,"Completed") -> 1
A11: Siti Rahayu | B11: =COUNTIF('Task Tracker'!C$5:C$200,A11) -> 3 | C11: =COUNTIFS('Task Tracker'!C$5:C$200,A11,'Task Tracker'!G$5:G$200,"Not Started") -> 2 | D11: =COUNTIFS('Task Tracker'!C$5:C$200,A11,'Task Tracker'!G$5:G$200,"In Progress") -> 0 | E11: =COUNTIFS('Task Tracker'!C$5:C$200,A11,'Task Tracker'!G$5:G$200,"In Review") -> 0 | F11: =COUNTIFS('Task Tracker'!C$5:C$200,A11,'Task Tracker'!G$5:G$200,"Completed") -> 1
A12: Budi Santoso | B12: =COUNTIF('Task Tracker'!C$5:C$200,A12) -> 2 | C12: =COUNTIFS('Task Tracker'!C$5:C$200,A12,'Task Tracker'!G$5:G$200,"Not Started") -> 0 | D12: =COUNTIFS('Task Tracker'!C$5:C$200,A12,'Task Tracker'!G$5:G$200,"In Progress") -> 1 | E12: =COUNTIFS('Task Tracker'!C$5:C$200,A12,'Task Tracker'!G$5:G$200,"In Review") -> 0 | F12: =COUNTIFS('Task Tracker'!C$5:C$200,A12,'Task Tracker'!G$5:G$200,"Completed") -> 1
A13: Dewi Lestari | B13: =COUNTIF('Task Tracker'!C$5:C$200,A13) -> 6 | C13: =COUNTIFS('Task Tracker'!C$5:C$200,A13,'Task Tracker'!G$5:G$200,"Not Started") -> 1 | D13: =COUNTIFS('Task Tracker'!C$5:C$200,A13,'Task Tracker'!G$5:G$200,"In Progress") -> 1 | E13: =COUNTIFS('Task Tracker'!C$5:C$200,A13,'Task Tracker'!G$5:G$200,"In Review") -> 2 | F13: =COUNTIFS('Task Tracker'!C$5:C$200,A13,'Task Tracker'!G$5:G$200,"Completed") -> 2
A14: Rizki Hidayat | B14: =COUNTIF('Task Tracker'!C$5:C$200,A14) -> 1 | C14: =COUNTIFS('Task Tracker'!C$5:C$200,A14,'Task Tracker'!G$5:G$200,"Not Started") -> 0 | D14: =COUNTIFS('Task Tracker'!C$5:C$200,A14,'Task Tracker'!G$5:G$200,"In Progress") -> 0 | E14: =COUNTIFS('Task Tracker'!C$5:C$200,A14,'Task Tracker'!G$5:G$200,"In Review") -> 1 | F14: =COUNTIFS('Task Tracker'!C$5:C$200,A14,'Task Tracker'!G$5:G$200,"Completed") -> 0
A15: Putri Wulandari | B15: =COUNTIF('Task Tracker'!C$5:C$200,A15) -> 1 | C15: =COUNTIFS('Task Tracker'!C$5:C$200,A15,'Task Tracker'!G$5:G$200,"Not Started") -> 0 | D15: =COUNTIFS('Task Tracker'!C$5:C$200,A15,'Task Tracker'!G$5:G$200,"In Progress") -> 0 | E15: =COUNTIFS('Task Tracker'!C$5:C$200,A15,'Task Tracker'!G$5:G$200,"In Review") -> 0 | F15: =COUNTIFS('Task Tracker'!C$5:C$200,A15,'Task Tracker'!G$5:G$200,"Completed") -> 1
A16: Fajar Nugroho | B16: =COUNTIF('Task Tracker'!C$5:C$200,A16) -> 4 | C16: =COUNTIFS('Task Tracker'!C$5:C$200,A16,'Task Tracker'!G$5:G$200,"Not Started") -> 0 | D16: =COUNTIFS('Task Tracker'!C$5:C$200,A16,'Task Tracker'!G$5:G$200,"In Progress") -> 1 | E16: =COUNTIFS('Task Tracker'!C$5:C$200,A16,'Task Tracker'!G$5:G$200,"In Review") -> 2 | F16: =COUNTIFS('Task Tracker'!C$5:C$200,A16,'Task Tracker'!G$5:G$200,"Completed") -> 1
A17: Anita Sari | B17: =COUNTIF('Task Tracker'!C$5:C$200,A17) -> 9 | C17: =COUNTIFS('Task Tracker'!C$5:C$200,A17,'Task Tracker'!G$5:G$200,"Not Started") -> 0 | D17: =COUNTIFS('Task Tracker'!C$5:C$200,A17,'Task Tracker'!G$5:G$200,"In Progress") -> 1 | E17: =COUNTIFS('Task Tracker'!C$5:C$200,A17,'Task Tracker'!G$5:G$200,"In Review") -> 1 | F17: =COUNTIFS('Task Tracker'!C$5:C$200,A17,'Task Tracker'!G$5:G$200,"Completed") -> 1
A18: Hendra Wijaya | B18: =COUNTIF('Task Tracker'!C$5:C$200,A18) -> 7 | C18: =COUNTIFS('Task Tracker'!C$5:C$200,A18,'Task Tracker'!G$5:G$200,"Not Started") -> 0 | D18: =COUNTIFS('Task Tracker'!C$5:C$200,A18,'Task Tracker'!G$5:G$200,"In Progress") -> 2 | E18: =COUNTIFS('Task Tracker'!C$5:C$200,A18,'Task Tracker'!G$5:G$200,"In Review") -> 1 | F18: =COUNTIFS('Task Tracker'!C$5:C$200,A18,'Task Tracker'!G$5:G$200,"Completed") -> 2
A19: Maya Kusuma | B19: =COUNTIF('Task Tracker'!C$5:C$200,A19) -> 2 | C19: =COUNTIFS('Task Tracker'!C$5:C$200,A19,'Task Tracker'!G$5:G$200,"Not Started") -> 0 | D19: =COUNTIFS('Task Tracker'!C$5:C$200,A19,'Task Tracker'!G$5:G$200,"In Progress") -> 0 | E19: =COUNTIFS('Task Tracker'!C$5:C$200,A19,'Task Tracker'!G$5:G$200,"In Review") -> 0 | F19: =COUNTIFS('Task Tracker'!C$5:C$200,A19,'Task Tracker'!G$5:G$200,"Completed") -> 0
A20: Dimas Prasetyo | B20: =COUNTIF('Task Tracker'!C$5:C$200,A20) -> 2 | C20: =COUNTIFS('Task Tracker'!C$5:C$200,A20,'Task Tracker'!G$5:G$200,"Not Started") -> 1 | D20: =COUNTIFS('Task Tracker'!C$5:C$200,A20,'Task Tracker'!G$5:G$200,"In Progress") -> 1 | E20: =COUNTIFS('Task Tracker'!C$5:C$200,A20,'Task Tracker'!G$5:G$200,"In Review") -> 0 | F20: =COUNTIFS('Task Tracker'!C$5:C$200,A20,'Task Tracker'!G$5:G$200,"Completed") -> 0
A21: Rina Fitriani | B21: =COUNTIF('Task Tracker'!C$5:C$200,A21) -> 1 | C21: =COUNTIFS('Task Tracker'!C$5:C$200,A21,'Task Tracker'!G$5:G$200,"Not Started") -> 0 | D21: =COUNTIFS('Task Tracker'!C$5:C$200,A21,'Task Tracker'!G$5:G$200,"In Progress") -> 0 | E21: =COUNTIFS('Task Tracker'!C$5:C$200,A21,'Task Tracker'!G$5:G$200,"In Review") -> 1 | F21: =COUNTIFS('Task Tracker'!C$5:C$200,A21,'Task Tracker'!G$5:G$200,"Completed") -> 0
A24: TASKS PER BRAND
A25: Brand | B25: Total | C25: Not Started | D25: In Progress | E25: In Review | F25: Completed
A26: Brand Alpha | B26: =COUNTIF('Task Tracker'!D$5:D$200,A26) -> 0 | C26: =COUNTIFS('Task Tracker'!D$5:D$200,A26,'Task Tracker'!G$5:G$200,"Not Started") -> 0 | D26: =COUNTIFS('Task Tracker'!D$5:D$200,A26,'Task Tracker'!G$5:G$200,"In Progress") -> 0 | E26: =COUNTIFS('Task Tracker'!D$5:D$200,A26,'Task Tracker'!G$5:G$200,"In Review") -> 0 | F26: =COUNTIFS('Task Tracker'!D$5:D$200,A26,'Task Tracker'!G$5:G$200,"Completed") -> 0
A27: Brand Beta | B27: =COUNTIF('Task Tracker'!D$5:D$200,A27) -> 0 | C27: =COUNTIFS('Task Tracker'!D$5:D$200,A27,'Task Tracker'!G$5:G$200,"Not Started") -> 0 | D27: =COUNTIFS('Task Tracker'!D$5:D$200,A27,'Task Tracker'!G$5:G$200,"In Progress") -> 0 | E27: =COUNTIFS('Task Tracker'!D$5:D$200,A27,'Task Tracker'!G$5:G$200,"In Review") -> 0 | F27: =COUNTIFS('Task Tracker'!D$5:D$200,A27,'Task Tracker'!G$5:G$200,"Completed") -> 0
A28: Brand Gamma | B28: =COUNTIF('Task Tracker'!D$5:D$200,A28) -> 0 | C28: =COUNTIFS('Task Tracker'!D$5:D$200,A28,'Task Tracker'!G$5:G$200,"Not Started") -> 0 | D28: =COUNTIFS('Task Tracker'!D$5:D$200,A28,'Task Tracker'!G$5:G$200,"In Progress") -> 0 | E28: =COUNTIFS('Task Tracker'!D$5:D$200,A28,'Task Tracker'!G$5:G$200,"In Review") -> 0 | F28: =COUNTIFS('Task Tracker'!D$5:D$200,A28,'Task Tracker'!G$5:G$200,"Completed") -> 0
A29: Brand Delta | B29: =COUNTIF('Task Tracker'!D$5:D$200,A29) -> 0 | C29: =COUNTIFS('Task Tracker'!D$5:D$200,A29,'Task Tracker'!G$5:G$200,"Not Started") -> 0 | D29: =COUNTIFS('Task Tracker'!D$5:D$200,A29,'Task Tracker'!G$5:G$200,"In Progress") -> 0 | E29: =COUNTIFS('Task Tracker'!D$5:D$200,A29,'Task Tracker'!G$5:G$200,"In Review") -> 0 | F29: =COUNTIFS('Task Tracker'!D$5:D$200,A29,'Task Tracker'!G$5:G$200,"Completed") -> 0
A30: Brand Epsilon | B30: =COUNTIF('Task Tracker'!D$5:D$200,A30) -> 0 | C30: =COUNTIFS('Task Tracker'!D$5:D$200,A30,'Task Tracker'!G$5:G$200,"Not Started") -> 0 | D30: =COUNTIFS('Task Tracker'!D$5:D$200,A30,'Task Tracker'!G$5:G$200,"In Progress") -> 0 | E30: =COUNTIFS('Task Tracker'!D$5:D$200,A30,'Task Tracker'!G$5:G$200,"In Review") -> 0 | F30: =COUNTIFS('Task Tracker'!D$5:D$200,A30,'Task Tracker'!G$5:G$200,"Completed") -> 0
